2019-04-17 13:46:38,153 [HttpRunnerManager:35] [operation:add_register_data] [INFO]- 新增用户：ApiManager.UserInfo.objects
2019-04-17 13:46:47,779 [HttpRunnerManager:56] [views:login] [INFO]- pengqiang 登录成功
2019-04-17 17:15:01,228 [django.request:228] [log:log_response] [WARNING]- Not Found: /
2019-04-17 17:16:26,709 [django.request:228] [log:log_response] [WARNING]- Not Found: /
2019-04-17 19:41:44,625 [django.request:228] [log:log_response] [WARNING]- Not Found: /api
2019-04-18 09:26:00,095 [HttpRunnerManager:56] [views:login] [INFO]- pengqiang 登录成功
2019-04-18 21:28:48,487 [django.request:228] [log:log_response] [WARNING]- Not Found: /
2019-04-18 21:29:07,270 [HttpRunnerManager:56] [views:login] [INFO]- pengqiang 登录成功
2019-04-19 21:17:24,758 [django.request:228] [log:log_response] [WARNING]- Not Found: /
2019-04-19 21:18:16,061 [HttpRunnerManager:56] [views:login] [INFO]- pengqiang 登录成功
2019-04-21 22:32:12,374 [HttpRunnerManager:59] [views:login] [INFO]- pengqiang 登录成功
2019-04-22 10:07:37,024 [django.request:228] [log:log_response] [WARNING]- Not Found: /
2019-04-22 10:07:43,994 [django.request:228] [log:log_response] [WARNING]- Not Found: /polls/
2019-04-22 10:11:10,271 [django.request:228] [log:log_response] [WARNING]- Not Found: /
2019-04-22 10:11:51,691 [HttpRunnerManager:59] [views:login] [INFO]- pengqiang 登录成功
2019-04-22 10:20:41,424 [HttpRunnerManager:62] [operation:add_project_data] [INFO]- 项目添加成功：{'project_name': 'cmis', 'responsible_name': 'ljp', 'test_user': 'pq', 'dev_user': 'sxw', 'publish_app': 'cmis', 'simple_desc': '', 'other_desc': ''}
2019-04-22 10:21:25,414 [HttpRunnerManager:110] [operation:add_module_data] [INFO]- 模块添加成功：{'module_name': '存款', 'test_user': 'pq', 'simple_desc': '', 'other_desc': '', 'belong_project': <ProjectInfo: ProjectInfo object (1)>}
2019-04-22 10:31:10,789 [HttpRunnerManager:154] [operation:add_case_data] [INFO]- 存款测试用例添加成功: {'test': {'request': {'url': 'cmis/100010', 'method': 'POST', 'data': {'id_no': '321312312'}}, 'name': '存款测试'}}
2019-04-22 14:40:40,683 [django.request:228] [log:log_response] [WARNING]- Not Found: /
2019-04-22 15:37:57,446 [django.request:228] [log:log_response] [WARNING]- Not Found: /
2019-04-22 15:38:14,574 [HttpRunnerManager:61] [views:login] [INFO]- pengqiang 登录成功
2019-04-23 10:36:50,061 [django.request:228] [log:log_response] [WARNING]- Not Found: /
2019-04-23 10:37:08,374 [HttpRunnerManager:67] [views:login] [INFO]- pengqiang 登录失败, 请检查用户名或者密码
2019-04-23 10:37:16,112 [HttpRunnerManager:67] [views:login] [INFO]- pengqiang 登录失败, 请检查用户名或者密码
2019-04-23 10:38:17,275 [HttpRunnerManager:35] [operation:add_register_data] [INFO]- 新增用户：ApiManager.UserInfo.objects
2019-04-23 10:38:24,609 [HttpRunnerManager:62] [views:login] [INFO]- pengqiang 登录成功
2019-04-23 15:04:15,669 [HttpRunnerManager:62] [operation:add_project_data] [INFO]- 项目添加成功：{'project_name': 'cmis', 'responsible_name': 'ljp', 'test_user': 'pq', 'dev_user': 'sxw', 'publish_app': 'cmis', 'simple_desc': '', 'other_desc': ''}
2019-04-23 15:05:52,905 [HttpRunnerManager:110] [operation:add_module_data] [INFO]- 模块添加成功：{'module_name': '存款', 'test_user': 'pq', 'simple_desc': '', 'other_desc': '', 'belong_project': <ProjectInfo: ProjectInfo object (1)>}
2019-04-23 15:42:25,246 [HttpRunnerManager:62] [views:login] [INFO]- pengqiang 登录成功
2019-04-23 17:03:50,106 [HttpRunnerManager:154] [operation:add_case_data] [INFO]- testapp用例添加成功: {'test': {'request': {'url': '/app/test', 'method': 'POST'}, 'name': 'testapp'}}
2019-04-23 17:57:17,624 [django.request:228] [log:log_response] [WARNING]- Not Found: /
2019-04-23 17:57:30,156 [django.request:228] [log:log_response] [ERROR]- Internal Server Error: /api/add_case/
Traceback (most recent call last):
  File "D:\Programs\Python\Python36\lib\site-packages\django\core\handlers\exception.py", line 34, in inner
    response = get_response(request)
  File "D:\Programs\Python\Python36\lib\site-packages\django\core\handlers\base.py", line 115, in _get_response
    response = self.process_exception_by_middleware(e, request)
  File "D:\Programs\Python\Python36\lib\site-packages\django\core\handlers\base.py", line 113, in _get_response
    response = wrapped_callback(request, *callback_args, **callback_kwargs)
  File "D:\Users\pq\PycharmProjects\hrm-test-dev\HttpRunnerManager\activator.py", line 10, in process
    app = __import__("%s.views" % app)
  File "D:\Users\pq\PycharmProjects\hrm-test-dev\ApiManager\views.py", line 19, in <module>
    from ApiManager.models import ProjectInfo, ModuleInfo, TestCaseInfo, UserInfo, EnvInfo, TestReports, DebugTalk, \
ImportError: cannot import name 'ExcelCase'
2019-04-23 17:57:40,153 [django.request:228] [log:log_response] [WARNING]- Not Found: /api/
2019-04-23 18:03:58,016 [django.request:228] [log:log_response] [WARNING]- Not Found: /
2019-04-23 18:17:34,533 [django.request:228] [log:log_response] [WARNING]- Not Found: /
2019-04-23 18:17:48,678 [HttpRunnerManager:60] [views:login] [INFO]- pengqiang 登录成功
2019-04-23 23:10:02,282 [django.request:228] [log:log_response] [WARNING]- Not Found: /
2019-04-23 23:10:17,465 [HttpRunnerManager:60] [views:login] [INFO]- pengqiang 登录成功
2019-04-24 09:36:51,939 [django.request:228] [log:log_response] [WARNING]- Not Found: /
2019-04-24 09:37:05,968 [HttpRunnerManager:60] [views:login] [INFO]- pengqiang 登录成功
2019-04-24 14:46:33,100 [HttpRunnerManager:60] [views:login] [INFO]- pengqiang 登录成功
2019-04-24 16:43:06,121 [django.request:228] [log:log_response] [WARNING]- Not Found: /
2019-04-24 16:43:32,630 [HttpRunnerManager:61] [views:login] [INFO]- pengqiang 登录成功
2019-04-24 16:44:21,419 [django.request:228] [log:log_response] [WARNING]- Not Found: /api/
2019-04-24 16:44:33,462 [HttpRunnerManager:61] [views:login] [INFO]- pengqiang 登录成功
2019-04-24 16:47:31,710 [django.request:228] [log:log_response] [WARNING]- Not Found: /
2019-04-24 17:43:06,511 [HttpRunnerManager:66] [views:login] [INFO]- pengqiang 登录失败, 请检查用户名或者密码
2019-04-24 17:43:11,305 [HttpRunnerManager:61] [views:login] [INFO]- pengqiang 登录成功
2019-04-24 19:37:29,842 [django.request:228] [log:log_response] [WARNING]- Not Found: /
2019-04-24 19:37:51,366 [HttpRunnerManager:62] [views:login] [INFO]- pengqiang 登录成功
2019-04-24 21:53:19,805 [django.request:228] [log:log_response] [WARNING]- Not Found: /import_paper/
2019-04-24 22:04:01,139 [django.request:228] [log:log_response] [WARNING]- Not Found: /import_paper/
2019-04-25 20:52:33,422 [django.request:228] [log:log_response] [WARNING]- Not Found: /
2019-04-25 20:52:45,746 [HttpRunnerManager:62] [views:login] [INFO]- pengqiang 登录成功
2019-04-26 09:49:24,757 [HttpRunnerManager:62] [views:login] [INFO]- pengqiang 登录成功
2019-04-26 09:56:08,244 [HttpRunnerManager:62] [views:login] [INFO]- pengqiang 登录成功
2019-04-26 09:58:06,356 [HttpRunnerManager:62] [views:login] [INFO]- pengqiang 登录成功
2019-04-26 11:13:47,712 [django.request:228] [log:log_response] [WARNING]- Not Found: /
2019-04-26 11:13:47,771 [django.request:228] [log:log_response] [WARNING]- Not Found: /
2019-04-26 11:14:09,566 [HttpRunnerManager:62] [views:login] [INFO]- pengqiang 登录成功
2019-04-26 11:18:54,723 [HttpRunnerManager:62] [views:login] [INFO]- pengqiang 登录成功
2019-04-26 13:51:52,085 [HttpRunnerManager:62] [views:login] [INFO]- pengqiang 登录成功
2019-04-26 16:20:03,120 [HttpRunnerManager:62] [views:login] [INFO]- pengqiang 登录成功
2019-04-26 16:20:48,553 [django.request:228] [log:log_response] [ERROR]- Internal Server Error: /api/upload_file/
Traceback (most recent call last):
  File "D:\Programs\Python\Python36\lib\site-packages\django\core\handlers\exception.py", line 34, in inner
    response = get_response(request)
  File "D:\Programs\Python\Python36\lib\site-packages\django\core\handlers\base.py", line 115, in _get_response
    response = self.process_exception_by_middleware(e, request)
  File "D:\Programs\Python\Python36\lib\site-packages\django\core\handlers\base.py", line 113, in _get_response
    response = wrapped_callback(request, *callback_args, **callback_kwargs)
  File "D:\Users\pq\PycharmProjects\hrm-test-dev\HttpRunnerManager\activator.py", line 15, in process
    result = fun(request, index) if index else fun(request)
  File "D:\Users\pq\PycharmProjects\hrm-test-dev\ApiManager\views.py", line 46, in wrapper
    return func(request, *args, **kwargs)
  File "D:\Users\pq\PycharmProjects\hrm-test-dev\ApiManager\views.py", line 646, in upload_file
    upload_file_logic(file_list, project_name, module_name, account)
  File "D:\Users\pq\PycharmProjects\hrm-test-dev\ApiManager\utils\common.py", line 541, in upload_file_logic
    for test_case in content:
UnboundLocalError: local variable 'content' referenced before assignment
2019-04-26 16:50:07,074 [django.request:228] [log:log_response] [ERROR]- Internal Server Error: /api/upload_file/
Traceback (most recent call last):
  File "D:\Programs\Python\Python36\lib\site-packages\django\core\handlers\exception.py", line 34, in inner
    response = get_response(request)
  File "D:\Programs\Python\Python36\lib\site-packages\django\core\handlers\base.py", line 115, in _get_response
    response = self.process_exception_by_middleware(e, request)
  File "D:\Programs\Python\Python36\lib\site-packages\django\core\handlers\base.py", line 113, in _get_response
    response = wrapped_callback(request, *callback_args, **callback_kwargs)
  File "D:\Users\pq\PycharmProjects\hrm-test-dev\HttpRunnerManager\activator.py", line 10, in process
    app = __import__("%s.views" % app)
  File "D:\Users\pq\PycharmProjects\hrm-test-dev\ApiManager\views.py", line 632
    request.FILES.
                 ^
SyntaxError: invalid syntax
2019-04-26 16:50:15,313 [django.request:228] [log:log_response] [ERROR]- Internal Server Error: /api/upload_file/
Traceback (most recent call last):
  File "D:\Programs\Python\Python36\lib\site-packages\django\core\handlers\exception.py", line 34, in inner
    response = get_response(request)
  File "D:\Programs\Python\Python36\lib\site-packages\django\core\handlers\base.py", line 115, in _get_response
    response = self.process_exception_by_middleware(e, request)
  File "D:\Programs\Python\Python36\lib\site-packages\django\core\handlers\base.py", line 113, in _get_response
    response = wrapped_callback(request, *callback_args, **callback_kwargs)
  File "D:\Users\pq\PycharmProjects\hrm-test-dev\HttpRunnerManager\activator.py", line 10, in process
    app = __import__("%s.views" % app)
  File "D:\Users\pq\PycharmProjects\hrm-test-dev\ApiManager\views.py", line 632
    request.FILES.
                 ^
SyntaxError: invalid syntax
2019-04-26 16:50:18,426 [django.request:228] [log:log_response] [ERROR]- Internal Server Error: /api/upload_file/
Traceback (most recent call last):
  File "D:\Programs\Python\Python36\lib\site-packages\django\core\handlers\exception.py", line 34, in inner
    response = get_response(request)
  File "D:\Programs\Python\Python36\lib\site-packages\django\core\handlers\base.py", line 115, in _get_response
    response = self.process_exception_by_middleware(e, request)
  File "D:\Programs\Python\Python36\lib\site-packages\django\core\handlers\base.py", line 113, in _get_response
    response = wrapped_callback(request, *callback_args, **callback_kwargs)
  File "D:\Users\pq\PycharmProjects\hrm-test-dev\HttpRunnerManager\activator.py", line 10, in process
    app = __import__("%s.views" % app)
  File "D:\Users\pq\PycharmProjects\hrm-test-dev\ApiManager\views.py", line 632
    request.FILES.
                 ^
SyntaxError: invalid syntax
2019-04-26 16:50:27,286 [django.request:228] [log:log_response] [ERROR]- Internal Server Error: /api/upload_file/
Traceback (most recent call last):
  File "D:\Programs\Python\Python36\lib\site-packages\django\core\handlers\exception.py", line 34, in inner
    response = get_response(request)
  File "D:\Programs\Python\Python36\lib\site-packages\django\core\handlers\base.py", line 115, in _get_response
    response = self.process_exception_by_middleware(e, request)
  File "D:\Programs\Python\Python36\lib\site-packages\django\core\handlers\base.py", line 113, in _get_response
    response = wrapped_callback(request, *callback_args, **callback_kwargs)
  File "D:\Users\pq\PycharmProjects\hrm-test-dev\HttpRunnerManager\activator.py", line 10, in process
    app = __import__("%s.views" % app)
  File "D:\Users\pq\PycharmProjects\hrm-test-dev\ApiManager\views.py", line 632
    request.FILES.
                 ^
SyntaxError: invalid syntax
2019-04-26 17:56:16,016 [django.request:228] [log:log_response] [ERROR]- Internal Server Error: /api/upload_file/
Traceback (most recent call last):
  File "D:\Programs\Python\Python36\lib\site-packages\django\db\backends\utils.py", line 84, in _execute
    return self.cursor.execute(sql, params)
  File "D:\Programs\Python\Python36\lib\site-packages\django\db\backends\mysql\base.py", line 71, in execute
    return self.cursor.execute(query, args)
  File "D:\Programs\Python\Python36\lib\site-packages\MySQLdb\cursors.py", line 206, in execute
    res = self._query(query)
  File "D:\Programs\Python\Python36\lib\site-packages\MySQLdb\cursors.py", line 312, in _query
    db.query(q)
  File "D:\Programs\Python\Python36\lib\site-packages\MySQLdb\connections.py", line 224, in query
    _mysql.connection.query(self, query)
MySQLdb._exceptions.OperationalError: (1054, "Unknown column 'project_name' in 'field list'")

The above exception was the direct cause of the following exception:

Traceback (most recent call last):
  File "D:\Programs\Python\Python36\lib\site-packages\django\core\handlers\exception.py", line 34, in inner
    response = get_response(request)
  File "D:\Programs\Python\Python36\lib\site-packages\django\core\handlers\base.py", line 115, in _get_response
    response = self.process_exception_by_middleware(e, request)
  File "D:\Programs\Python\Python36\lib\site-packages\django\core\handlers\base.py", line 113, in _get_response
    response = wrapped_callback(request, *callback_args, **callback_kwargs)
  File "D:\Users\pq\PycharmProjects\hrm-test-dev\HttpRunnerManager\activator.py", line 15, in process
    result = fun(request, index) if index else fun(request)
  File "D:\Users\pq\PycharmProjects\hrm-test-dev\ApiManager\views.py", line 44, in wrapper
    return func(request, *args, **kwargs)
  File "D:\Users\pq\PycharmProjects\hrm-test-dev\ApiManager\views.py", line 650, in upload_file
    ec.save()
  File "D:\Programs\Python\Python36\lib\site-packages\django\db\models\base.py", line 741, in save
    force_update=force_update, update_fields=update_fields)
  File "D:\Programs\Python\Python36\lib\site-packages\django\db\models\base.py", line 779, in save_base
    force_update, using, update_fields,
  File "D:\Programs\Python\Python36\lib\site-packages\django\db\models\base.py", line 870, in _save_table
    result = self._do_insert(cls._base_manager, using, fields, update_pk, raw)
  File "D:\Programs\Python\Python36\lib\site-packages\django\db\models\base.py", line 908, in _do_insert
    using=using, raw=raw)
  File "D:\Programs\Python\Python36\lib\site-packages\django\db\models\manager.py", line 82, in manager_method
    return getattr(self.get_queryset(), name)(*args, **kwargs)
  File "D:\Programs\Python\Python36\lib\site-packages\django\db\models\query.py", line 1186, in _insert
    return query.get_compiler(using=using).execute_sql(return_id)
  File "D:\Programs\Python\Python36\lib\site-packages\django\db\models\sql\compiler.py", line 1332, in execute_sql
    cursor.execute(sql, params)
  File "D:\Programs\Python\Python36\lib\site-packages\django\db\backends\utils.py", line 99, in execute
    return super().execute(sql, params)
  File "D:\Programs\Python\Python36\lib\site-packages\django\db\backends\utils.py", line 67, in execute
    return self._execute_with_wrappers(sql, params, many=False, executor=self._execute)
  File "D:\Programs\Python\Python36\lib\site-packages\django\db\backends\utils.py", line 76, in _execute_with_wrappers
    return executor(sql, params, many, context)
  File "D:\Programs\Python\Python36\lib\site-packages\django\db\backends\utils.py", line 84, in _execute
    return self.cursor.execute(sql, params)
  File "D:\Programs\Python\Python36\lib\site-packages\django\db\utils.py", line 89, in __exit__
    raise dj_exc_value.with_traceback(traceback) from exc_value
  File "D:\Programs\Python\Python36\lib\site-packages\django\db\backends\utils.py", line 84, in _execute
    return self.cursor.execute(sql, params)
  File "D:\Programs\Python\Python36\lib\site-packages\django\db\backends\mysql\base.py", line 71, in execute
    return self.cursor.execute(query, args)
  File "D:\Programs\Python\Python36\lib\site-packages\MySQLdb\cursors.py", line 206, in execute
    res = self._query(query)
  File "D:\Programs\Python\Python36\lib\site-packages\MySQLdb\cursors.py", line 312, in _query
    db.query(q)
  File "D:\Programs\Python\Python36\lib\site-packages\MySQLdb\connections.py", line 224, in query
    _mysql.connection.query(self, query)
django.db.utils.OperationalError: (1054, "Unknown column 'project_name' in 'field list'")
2019-04-26 18:03:45,736 [django.request:228] [log:log_response] [ERROR]- Internal Server Error: /api/upload_file/
Traceback (most recent call last):
  File "D:\Programs\Python\Python36\lib\site-packages\django\db\backends\utils.py", line 84, in _execute
    return self.cursor.execute(sql, params)
  File "D:\Programs\Python\Python36\lib\site-packages\django\db\backends\mysql\base.py", line 71, in execute
    return self.cursor.execute(query, args)
  File "D:\Programs\Python\Python36\lib\site-packages\MySQLdb\cursors.py", line 206, in execute
    res = self._query(query)
  File "D:\Programs\Python\Python36\lib\site-packages\MySQLdb\cursors.py", line 312, in _query
    db.query(q)
  File "D:\Programs\Python\Python36\lib\site-packages\MySQLdb\connections.py", line 224, in query
    _mysql.connection.query(self, query)
MySQLdb._exceptions.OperationalError: (1054, "Unknown column 'project_name' in 'field list'")

The above exception was the direct cause of the following exception:

Traceback (most recent call last):
  File "D:\Programs\Python\Python36\lib\site-packages\django\core\handlers\exception.py", line 34, in inner
    response = get_response(request)
  File "D:\Programs\Python\Python36\lib\site-packages\django\core\handlers\base.py", line 115, in _get_response
    response = self.process_exception_by_middleware(e, request)
  File "D:\Programs\Python\Python36\lib\site-packages\django\core\handlers\base.py", line 113, in _get_response
    response = wrapped_callback(request, *callback_args, **callback_kwargs)
  File "D:\Users\pq\PycharmProjects\hrm-test-dev\HttpRunnerManager\activator.py", line 15, in process
    result = fun(request, index) if index else fun(request)
  File "D:\Users\pq\PycharmProjects\hrm-test-dev\ApiManager\views.py", line 44, in wrapper
    return func(request, *args, **kwargs)
  File "D:\Users\pq\PycharmProjects\hrm-test-dev\ApiManager\views.py", line 650, in upload_file
    ec.save()
  File "D:\Programs\Python\Python36\lib\site-packages\django\db\models\base.py", line 741, in save
    force_update=force_update, update_fields=update_fields)
  File "D:\Programs\Python\Python36\lib\site-packages\django\db\models\base.py", line 779, in save_base
    force_update, using, update_fields,
  File "D:\Programs\Python\Python36\lib\site-packages\django\db\models\base.py", line 870, in _save_table
    result = self._do_insert(cls._base_manager, using, fields, update_pk, raw)
  File "D:\Programs\Python\Python36\lib\site-packages\django\db\models\base.py", line 908, in _do_insert
    using=using, raw=raw)
  File "D:\Programs\Python\Python36\lib\site-packages\django\db\models\manager.py", line 82, in manager_method
    return getattr(self.get_queryset(), name)(*args, **kwargs)
  File "D:\Programs\Python\Python36\lib\site-packages\django\db\models\query.py", line 1186, in _insert
    return query.get_compiler(using=using).execute_sql(return_id)
  File "D:\Programs\Python\Python36\lib\site-packages\django\db\models\sql\compiler.py", line 1332, in execute_sql
    cursor.execute(sql, params)
  File "D:\Programs\Python\Python36\lib\site-packages\django\db\backends\utils.py", line 99, in execute
    return super().execute(sql, params)
  File "D:\Programs\Python\Python36\lib\site-packages\django\db\backends\utils.py", line 67, in execute
    return self._execute_with_wrappers(sql, params, many=False, executor=self._execute)
  File "D:\Programs\Python\Python36\lib\site-packages\django\db\backends\utils.py", line 76, in _execute_with_wrappers
    return executor(sql, params, many, context)
  File "D:\Programs\Python\Python36\lib\site-packages\django\db\backends\utils.py", line 84, in _execute
    return self.cursor.execute(sql, params)
  File "D:\Programs\Python\Python36\lib\site-packages\django\db\utils.py", line 89, in __exit__
    raise dj_exc_value.with_traceback(traceback) from exc_value
  File "D:\Programs\Python\Python36\lib\site-packages\django\db\backends\utils.py", line 84, in _execute
    return self.cursor.execute(sql, params)
  File "D:\Programs\Python\Python36\lib\site-packages\django\db\backends\mysql\base.py", line 71, in execute
    return self.cursor.execute(query, args)
  File "D:\Programs\Python\Python36\lib\site-packages\MySQLdb\cursors.py", line 206, in execute
    res = self._query(query)
  File "D:\Programs\Python\Python36\lib\site-packages\MySQLdb\cursors.py", line 312, in _query
    db.query(q)
  File "D:\Programs\Python\Python36\lib\site-packages\MySQLdb\connections.py", line 224, in query
    _mysql.connection.query(self, query)
django.db.utils.OperationalError: (1054, "Unknown column 'project_name' in 'field list'")
2019-04-26 23:51:13,253 [HttpRunnerManager:60] [views:login] [INFO]- pengqiang 登录成功
2019-04-27 00:09:50,214 [django.request:228] [log:log_response] [ERROR]- Internal Server Error: /api/upload_file/
Traceback (most recent call last):
  File "D:\Programs\Python\Python36\lib\site-packages\django\core\handlers\exception.py", line 34, in inner
    response = get_response(request)
  File "D:\Programs\Python\Python36\lib\site-packages\django\core\handlers\base.py", line 115, in _get_response
    response = self.process_exception_by_middleware(e, request)
  File "D:\Programs\Python\Python36\lib\site-packages\django\core\handlers\base.py", line 113, in _get_response
    response = wrapped_callback(request, *callback_args, **callback_kwargs)
  File "D:\Users\pq\PycharmProjects\hrm-test-dev\HttpRunnerManager\activator.py", line 15, in process
    result = fun(request, index) if index else fun(request)
  File "D:\Users\pq\PycharmProjects\hrm-test-dev\ApiManager\views.py", line 44, in wrapper
    return func(request, *args, **kwargs)
  File "D:\Users\pq\PycharmProjects\hrm-test-dev\ApiManager\views.py", line 651, in upload_file
    wb.release_resources()
UnboundLocalError: local variable 'wb' referenced before assignment
2019-04-27 00:23:58,791 [django.request:228] [log:log_response] [ERROR]- Internal Server Error: /api/upload_file/
Traceback (most recent call last):
  File "D:\Programs\Python\Python36\lib\site-packages\django\utils\datastructures.py", line 78, in __getitem__
    list_ = super().__getitem__(key)
KeyError: 'upload'

During handling of the above exception, another exception occurred:

Traceback (most recent call last):
  File "D:\Programs\Python\Python36\lib\site-packages\django\core\handlers\exception.py", line 34, in inner
    response = get_response(request)
  File "D:\Programs\Python\Python36\lib\site-packages\django\core\handlers\base.py", line 115, in _get_response
    response = self.process_exception_by_middleware(e, request)
  File "D:\Programs\Python\Python36\lib\site-packages\django\core\handlers\base.py", line 113, in _get_response
    response = wrapped_callback(request, *callback_args, **callback_kwargs)
  File "D:\Users\pq\PycharmProjects\hrm-test-dev\HttpRunnerManager\activator.py", line 15, in process
    result = fun(request, index) if index else fun(request)
  File "D:\Users\pq\PycharmProjects\hrm-test-dev\ApiManager\views.py", line 44, in wrapper
    return func(request, *args, **kwargs)
  File "D:\Users\pq\PycharmProjects\hrm-test-dev\ApiManager\views.py", line 632, in upload_file
    excel_file = request.FILES['upload']
  File "D:\Programs\Python\Python36\lib\site-packages\django\utils\datastructures.py", line 80, in __getitem__
    raise MultiValueDictKeyError(key)
django.utils.datastructures.MultiValueDictKeyError: 'upload'
2019-04-27 10:08:40,481 [django.request:228] [log:log_response] [WARNING]- Not Found: /
2019-04-27 10:08:54,078 [HttpRunnerManager:60] [views:login] [INFO]- pengqiang 登录成功
2019-04-27 10:09:24,925 [HttpRunnerManager:192] [operation:add_config_data] [INFO]- testcase description配置添加成功: {'config': {'name': 'testcase description', 'variables': {}}}
2019-04-27 10:09:24,936 [HttpRunnerManager:154] [operation:add_case_data] [INFO]- /api/get-token用例添加成功: {'test': {'name': '/api/get-token', 'request': {'headers': {'Content-Type': 'application/json', 'User-Agent': 'python-requests/2.18.4', 'app_version': '2.8.6', 'device_sn': 'FwgRiO7CNA50DSU', 'os_platform': 'ios'}, 'json': {'sign': '9c0c7e51c91ae963c833a4ccbab8d683c4a90c98'}, 'method': 'POST', 'url': 'http://127.0.0.1:5000/api/get-token'}, 'validate': [{'check': 'status_code', 'comparator': 'eq', 'expected': 200}, {'check': 'headers.Content-Type', 'comparator': 'eq', 'expected': 'application/json'}, {'check': 'content.success', 'comparator': 'eq', 'expected': True}, {'check': 'content.token', 'comparator': 'eq', 'expected': 'baNLX1zhFYP11Seb'}]}}
2019-04-27 10:09:24,946 [HttpRunnerManager:154] [operation:add_case_data] [INFO]- /api/users/1000用例添加成功: {'test': {'name': '/api/users/1000', 'request': {'headers': {'Content-Type': 'application/json', 'User-Agent': 'python-requests/2.18.4', 'device_sn': 'FwgRiO7CNA50DSU', 'token': 'baNLX1zhFYP11Seb'}, 'json': {'name': 'user1', 'password': '123456'}, 'method': 'POST', 'url': 'http://127.0.0.1:5000/api/users/1000'}, 'validate': [{'check': 'status_code', 'comparator': 'eq', 'expected': 201}, {'check': 'headers.Content-Type', 'comparator': 'eq', 'expected': 'application/json'}, {'check': 'content.success', 'comparator': 'eq', 'expected': True}, {'check': 'content.msg', 'comparator': 'eq', 'expected': 'user created successfully.'}]}}
2019-04-27 13:20:44,733 [HttpRunnerManager:192] [operation:add_config_data] [INFO]- testcase description配置添加成功: {'config': {'name': 'testcase description', 'variables': {}}}
2019-04-27 13:20:44,749 [HttpRunnerManager:154] [operation:add_case_data] [INFO]- /api/get-token用例添加成功: {'test': {'name': '/api/get-token', 'request': {'headers': {'Content-Type': 'application/json', 'User-Agent': 'python-requests/2.18.4', 'app_version': '2.8.6', 'device_sn': 'FwgRiO7CNA50DSU', 'os_platform': 'ios'}, 'json': {'sign': '9c0c7e51c91ae963c833a4ccbab8d683c4a90c98'}, 'method': 'POST', 'url': 'http://127.0.0.1:5000/api/get-token'}, 'validate': [{'check': 'status_code', 'comparator': 'eq', 'expected': 200}, {'check': 'headers.Content-Type', 'comparator': 'eq', 'expected': 'application/json'}, {'check': 'content.success', 'comparator': 'eq', 'expected': True}, {'check': 'content.token', 'comparator': 'eq', 'expected': 'baNLX1zhFYP11Seb'}]}}
2019-04-27 13:20:44,764 [HttpRunnerManager:154] [operation:add_case_data] [INFO]- /api/users/1000用例添加成功: {'test': {'name': '/api/users/1000', 'request': {'headers': {'Content-Type': 'application/json', 'User-Agent': 'python-requests/2.18.4', 'device_sn': 'FwgRiO7CNA50DSU', 'token': 'baNLX1zhFYP11Seb'}, 'json': {'name': 'user1', 'password': '123456'}, 'method': 'POST', 'url': 'http://127.0.0.1:5000/api/users/1000'}, 'validate': [{'check': 'status_code', 'comparator': 'eq', 'expected': 201}, {'check': 'headers.Content-Type', 'comparator': 'eq', 'expected': 'application/json'}, {'check': 'content.success', 'comparator': 'eq', 'expected': True}, {'check': 'content.msg', 'comparator': 'eq', 'expected': 'user created successfully.'}]}}
2019-04-27 13:21:55,215 [django.request:228] [log:log_response] [ERROR]- Internal Server Error: /api/upload_file/
Traceback (most recent call last):
  File "D:\Programs\Python\Python36\lib\site-packages\django\core\handlers\exception.py", line 34, in inner
    response = get_response(request)
  File "D:\Programs\Python\Python36\lib\site-packages\django\core\handlers\base.py", line 115, in _get_response
    response = self.process_exception_by_middleware(e, request)
  File "D:\Programs\Python\Python36\lib\site-packages\django\core\handlers\base.py", line 113, in _get_response
    response = wrapped_callback(request, *callback_args, **callback_kwargs)
  File "D:\Users\pq\PycharmProjects\hrm-test-dev\HttpRunnerManager\activator.py", line 15, in process
    result = fun(request, index) if index else fun(request)
  File "D:\Users\pq\PycharmProjects\hrm-test-dev\ApiManager\views.py", line 44, in wrapper
    return func(request, *args, **kwargs)
  File "D:\Users\pq\PycharmProjects\hrm-test-dev\ApiManager\views.py", line 630, in upload_file
    os.mkdir(upload_path)
PermissionError: [WinError 5] 拒绝访问。: 'D:\\Users\\pq\\PycharmProjects\\hrm-test-dev\\upload\\'
2019-04-27 13:26:26,301 [HttpRunnerManager:192] [operation:add_config_data] [INFO]- testcase description配置添加成功: {'config': {'name': 'testcase description', 'variables': {}}}
2019-04-27 13:42:37,330 [HttpRunnerManager:154] [operation:add_case_data] [INFO]- /api/get-token用例添加成功: {'test': {'name': '/api/get-token', 'request': {'headers': {'Content-Type': 'application/json', 'User-Agent': 'python-requests/2.18.4', 'app_version': '2.8.6', 'device_sn': 'FwgRiO7CNA50DSU', 'os_platform': 'ios'}, 'json': {'sign': '9c0c7e51c91ae963c833a4ccbab8d683c4a90c98'}, 'method': 'POST', 'url': 'http://127.0.0.1:5000/api/get-token'}, 'validate': [{'check': 'status_code', 'comparator': 'eq', 'expected': 200}, {'check': 'headers.Content-Type', 'comparator': 'eq', 'expected': 'application/json'}, {'check': 'content.success', 'comparator': 'eq', 'expected': True}, {'check': 'content.token', 'comparator': 'eq', 'expected': 'baNLX1zhFYP11Seb'}]}}
2019-04-27 13:43:47,974 [HttpRunnerManager:154] [operation:add_case_data] [INFO]- /api/users/1000用例添加成功: {'test': {'name': '/api/users/1000', 'request': {'headers': {'Content-Type': 'application/json', 'User-Agent': 'python-requests/2.18.4', 'device_sn': 'FwgRiO7CNA50DSU', 'token': 'baNLX1zhFYP11Seb'}, 'json': {'name': 'user1', 'password': '123456'}, 'method': 'POST', 'url': 'http://127.0.0.1:5000/api/users/1000'}, 'validate': [{'check': 'status_code', 'comparator': 'eq', 'expected': 201}, {'check': 'headers.Content-Type', 'comparator': 'eq', 'expected': 'application/json'}, {'check': 'content.success', 'comparator': 'eq', 'expected': True}, {'check': 'content.msg', 'comparator': 'eq', 'expected': 'user created successfully.'}]}}
2019-04-27 21:33:07,732 [HttpRunnerManager:60] [views:login] [INFO]- pengqiang 登录成功
2019-04-27 21:45:04,381 [HttpRunnerManager:192] [operation:add_config_data] [INFO]- testcase description配置添加成功: {'config': {'name': 'testcase description', 'variables': {}}}
2019-04-27 21:45:04,433 [HttpRunnerManager:154] [operation:add_case_data] [INFO]- /api/get-token用例添加成功: {'test': {'name': '/api/get-token', 'request': {'headers': {'Content-Type': 'application/json', 'User-Agent': 'python-requests/2.18.4', 'app_version': '2.8.6', 'device_sn': 'FwgRiO7CNA50DSU', 'os_platform': 'ios'}, 'json': {'sign': '9c0c7e51c91ae963c833a4ccbab8d683c4a90c98'}, 'method': 'POST', 'url': 'http://127.0.0.1:5000/api/get-token'}, 'validate': [{'check': 'status_code', 'comparator': 'eq', 'expected': 200}, {'check': 'headers.Content-Type', 'comparator': 'eq', 'expected': 'application/json'}, {'check': 'content.success', 'comparator': 'eq', 'expected': True}, {'check': 'content.token', 'comparator': 'eq', 'expected': 'baNLX1zhFYP11Seb'}]}}
2019-04-27 21:45:04,478 [HttpRunnerManager:154] [operation:add_case_data] [INFO]- /api/users/1000用例添加成功: {'test': {'name': '/api/users/1000', 'request': {'headers': {'Content-Type': 'application/json', 'User-Agent': 'python-requests/2.18.4', 'device_sn': 'FwgRiO7CNA50DSU', 'token': 'baNLX1zhFYP11Seb'}, 'json': {'name': 'user1', 'password': '123456'}, 'method': 'POST', 'url': 'http://127.0.0.1:5000/api/users/1000'}, 'validate': [{'check': 'status_code', 'comparator': 'eq', 'expected': 201}, {'check': 'headers.Content-Type', 'comparator': 'eq', 'expected': 'application/json'}, {'check': 'content.success', 'comparator': 'eq', 'expected': True}, {'check': 'content.msg', 'comparator': 'eq', 'expected': 'user created successfully.'}]}}
2019-04-27 22:10:43,138 [HttpRunnerManager:60] [views:login] [INFO]- pengqiang 登录成功
2019-04-28 09:37:50,285 [HttpRunnerManager:60] [views:login] [INFO]- pengqiang 登录成功
2019-04-28 17:16:26,698 [HttpRunnerManager:60] [views:login] [INFO]- pengqiang 登录成功
2019-04-28 17:34:15,248 [django.request:228] [log:log_response] [WARNING]- Not Found: /
2019-04-28 17:35:09,511 [HttpRunnerManager:65] [views:login] [INFO]- pengqiang 登录失败, 请检查用户名或者密码
2019-04-28 17:36:34,201 [HttpRunnerManager:35] [operation:add_register_data] [INFO]- 新增用户：ApiManager.UserInfo.objects
2019-04-28 17:36:36,352 [HttpRunnerManager:60] [views:login] [INFO]- pengqiang 登录成功
2019-04-28 17:37:22,874 [HttpRunnerManager:62] [operation:add_project_data] [INFO]- 项目添加成功：{'project_name': 'cmis', 'responsible_name': 'ljp', 'test_user': 'pq', 'dev_user': 'sxw', 'publish_app': 'cmis_1', 'simple_desc': '', 'other_desc': ''}
2019-04-28 17:37:52,441 [HttpRunnerManager:110] [operation:add_module_data] [INFO]- 模块添加成功：{'module_name': '存款', 'test_user': 'pq', 'simple_desc': '', 'other_desc': '', 'belong_project': <ProjectInfo: ProjectInfo object (1)>}
2019-04-28 17:39:00,488 [HttpRunnerManager:192] [operation:add_config_data] [INFO]- testcase description配置添加成功: {'config': {'name': 'testcase description', 'variables': {}}}
2019-04-28 17:39:00,503 [HttpRunnerManager:154] [operation:add_case_data] [INFO]- /api/get-token用例添加成功: {'test': {'name': '/api/get-token', 'request': {'headers': {'Content-Type': 'application/json', 'User-Agent': 'python-requests/2.18.4', 'app_version': '2.8.6', 'device_sn': 'FwgRiO7CNA50DSU', 'os_platform': 'ios'}, 'json': {'sign': '9c0c7e51c91ae963c833a4ccbab8d683c4a90c98'}, 'method': 'POST', 'url': 'http://127.0.0.1:5000/api/get-token'}, 'validate': [{'check': 'status_code', 'comparator': 'eq', 'expected': 200}, {'check': 'headers.Content-Type', 'comparator': 'eq', 'expected': 'application/json'}, {'check': 'content.success', 'comparator': 'eq', 'expected': True}, {'check': 'content.token', 'comparator': 'eq', 'expected': 'baNLX1zhFYP11Seb'}]}}
2019-04-28 17:39:00,520 [HttpRunnerManager:154] [operation:add_case_data] [INFO]- /api/users/1000用例添加成功: {'test': {'name': '/api/users/1000', 'request': {'headers': {'Content-Type': 'application/json', 'User-Agent': 'python-requests/2.18.4', 'device_sn': 'FwgRiO7CNA50DSU', 'token': 'baNLX1zhFYP11Seb'}, 'json': {'name': 'user1', 'password': '123456'}, 'method': 'POST', 'url': 'http://127.0.0.1:5000/api/users/1000'}, 'validate': [{'check': 'status_code', 'comparator': 'eq', 'expected': 201}, {'check': 'headers.Content-Type', 'comparator': 'eq', 'expected': 'application/json'}, {'check': 'content.success', 'comparator': 'eq', 'expected': True}, {'check': 'content.msg', 'comparator': 'eq', 'expected': 'user created successfully.'}]}}
2019-04-28 17:39:13,195 [django.request:228] [log:log_response] [ERROR]- Internal Server Error: /api/upload_file/
Traceback (most recent call last):
  File "D:\Programs\Python\Python36\lib\site-packages\django\core\handlers\exception.py", line 34, in inner
    response = get_response(request)
  File "D:\Programs\Python\Python36\lib\site-packages\django\core\handlers\base.py", line 115, in _get_response
    response = self.process_exception_by_middleware(e, request)
  File "D:\Programs\Python\Python36\lib\site-packages\django\core\handlers\base.py", line 113, in _get_response
    response = wrapped_callback(request, *callback_args, **callback_kwargs)
  File "D:\Users\pq\PycharmProjects\hrm-test-dev\HttpRunnerManager\activator.py", line 15, in process
    result = fun(request, index) if index else fun(request)
  File "D:\Users\pq\PycharmProjects\hrm-test-dev\ApiManager\views.py", line 44, in wrapper
    return func(request, *args, **kwargs)
  File "D:\Users\pq\PycharmProjects\hrm-test-dev\ApiManager\views.py", line 677, in upload_file
    ec.belong_module = module_name
  File "D:\Programs\Python\Python36\lib\site-packages\django\db\models\fields\related_descriptors.py", line 211, in __set__
    self.field.remote_field.model._meta.object_name,
ValueError: Cannot assign "'1'": "ExcelCase.belong_module" must be a "ModuleInfo" instance.
2019-04-29 09:25:16,238 [HttpRunnerManager:60] [views:login] [INFO]- pengqiang 登录成功
2019-04-29 09:50:42,828 [HttpRunnerManager:110] [operation:add_module_data] [INFO]- 模块添加成功：{'module_name': '还款', 'test_user': 'pq', 'simple_desc': '', 'other_desc': '', 'belong_project': <ProjectInfo: ProjectInfo object (1)>}
2019-04-29 09:51:33,128 [HttpRunnerManager:62] [operation:add_project_data] [INFO]- 项目添加成功：{'project_name': 'cas', 'responsible_name': 'qwe', 'test_user': 'rty', 'dev_user': 'asd', 'publish_app': 'cas2', 'simple_desc': '', 'other_desc': ''}
2019-04-29 09:53:30,910 [HttpRunnerManager:110] [operation:add_module_data] [INFO]- 模块添加成功：{'module_name': '还款', 'test_user': 'rty', 'simple_desc': '', 'other_desc': '', 'belong_project': <ProjectInfo: ProjectInfo object (2)>}
